Workbook
Name DataDate: [1]OfDates!$B$2
Name DataWuenic: [1]OfDates!$B$4
Name DataYear: [1]OfDates!$B$6
Name DDL_Private: [2]drop_down_lists!$G$60:$G$63
Name DDL_target_group: [3]drop_down_lists!$G$3:$G$4
Name DDL_target_group_vitA: [3]drop_down_lists!$G$7:$G$10
Name DDL_target_TT: [3]drop_down_lists!$G$12:$G$13
Name DDL_yes_no_NR_ND: [2]drop_down_lists!$F$33:$F$36
Name Filename: [4]drop_down_lists!$H$3
Name Usys_Xprt_IndicatorTextT: #REF!
Name WHOUNICEF_MCV1: #REF!
Name WHOUNICEF_MCV2: #REF!
Name world_whounicef: #REF!
Name zCountryProfile_ScheduleT_2003: #REF!

Sheet TOC
A1: Table of contents
A3: 1 | B3: Overview of key demand forecasting assumptions including MR-MAP country grouping, introduction dates for four scenarios, WB income classification.
A4: 2 | B4: Target population data
A5: 2a | B5: Surviving infant population
A6: 2b | B6: 2 year old population
A7: 2c | B7: Under 2 year old population
A8: 2d | B8: % of under 2 year old population to total population (defined as to 65 years of age)
A9: 2e | B9: 2 to 15 years old poplation
A10: 2f | B10: % of under 2 to 15 year old population to total population (defined as to 65 years of age)
A11: 2g | B11: Under 5 year old population
A12: 3 | B12: Hard-to-Reach and MOV populations
A13: 3a | B13: Pecentage of MOVs occurring at 2 years old
A14: 3b | B14: Security compromised population
A15: 3c | B15: Rural population
A16: 3d | B16: Percentage of remote rural population to total rural population
A17: 3e | B17: Slum population
A18: 4 | B18: Coverage assumptions
A19: 4a | B19: Forecasted MCV1 estimates
A20: 4b | B20: Forecasted MCV2 estimates
A21: 4c | B21: Percentage of hard to reach and MOV populations that are under 2 years of age and being reached by a MR-MAP but not by a N/S presentation
A22: 4d | B22: Percentage of hard to reach populations that are betwee 2 to 15 years of age and being reached by a MR-MAP but not by a N/S presentation
A23: 5 | B23: Wastage rates for N/S and routine administration
A24: 6 | B24: Assumptions related to the dimensions of the MR-MAP Use Cases
A25: 6a | B25: Percentage of doses administered at a fixed post during routine imminuzation
A26: 6b | B26: Percentage of doses administered at a fixed post during SIA
A27: 6c | B27: Ratio of CHW to HW
A28: 7 | B28: Market penetration assumptions
A29: 7a | B29: MR-MAP UC1 Market penetration
A30: 7b | B30: MR-MAP UC2 Market penetration
A31: 7c | B31: MR-MAP UC3&4 Market penetration
A32: 8 | B32: Data utilized to estimate country adoption year of MR-MAPs
A33: 8a | B33: Historical introduction dates for MCV2, rubella, pneumococcal conjugate, rotavirus, and human papillomavirus vaccines
A34: 8b | B34: Total disease burden of measles and rubella (2019 reported annual cases and deaths of measles, 2019 measles incidence rate, and 2010 number of estimated rubella cases
A35: 8c | B35: The percentage of total expenditure on vaccines funded by the government (%) for the last available year or the forecasted Gavi eligibility status in 2030
A36: 8d | B36: Calculation for adoption dates for S1- Base scenario
A37: 8e | B37: Calculation for adoption dates for S3- Countries in greatest need intro dates

Sheet 1. Overview
A1: Overview of Country Assumptions
A4: Country | B4: ISO code | C4: WHO | D4: WB Group (June 2020) | E4: MR MAP Group | F4: Scenario 1: Base | G4: Scenario 2: regional pilots | H4: Scenario 3: countries with greatest need introduce first
A5: Afghanistan | B5: AFG | C5: EMRO | D5: Low income | E5: Key | F5: 2033 | G5: 2034 | H5: 2033
A6: Albania | B6: ALB | C6: EURO | D6: Upper middle income | E6: 1 | F6: 2036 | G6: 2036 | H6: 2035
A7: Algeria | B7: DZA | C7: AFRO | D7: Lower middle income | E7: 2 | F7: 2032 | G7: 2033 | H7: 2034
A8: Andorra | B8: AND | C8: EURO | D8: High income | E8: 1 | F8: 2039 | G8: 2039 | H8: 2039
A9: Angola | B9: AGO | C9: AFRO | D9: Lower middle income | E9: 3 | F9: 2033 | G9: 2033 | H9: 2030
A10: Antigua And Barbuda | B10: ATG | C10: PAHO | D10: High income | E10: 1 | F10: 2040 | G10: 2040 | H10: 2042
A11: Argentina | B11: ARG | C11: PAHO | D11: Upper middle income | E11: 1 | F11: 2037 | G11: 2938 | H11: 2039
A12: Armenia | B12: ARM | C12: EURO | D12: Upper middle income | E12: 1 | F12: 2040 | G12: 2040 | H12: 2040
A13: Australia | B13: AUS | C13: WPRO | D13: High income | E13: 1 | F13: 2031 | G13: 2031 | H13: 2033
A14: Austria | B14: AUT | C14: EURO | D14: High income | E14: 1 | F14: 2030 | G14: 2030 | H14: 2031
A15: Azerbaijan | B15: AZE | C15: EURO | D15: Upper middle income | E15: 1 | F15: 2038 | G15: 2038 | H15: 2039
A16: Bahamas | B16: BHS | C16: PAHO | D16: High income | E16: 1 | F16: 2037 | G16: 2938 | H16: 2040
A17: Bahrain | B17: BHR | C17: EMRO | D17: High income | E17: 1 | F17: 2034 | G17: 2034 | H17: 2037
A18: Bangladesh | B18: BGD | C18: SEARO | D18: Lower middle income | E18: Key | F18: 2034 | G18: 2034 | H18: 2034
A19: Barbados | B19: BRB | C19: PAHO | D19: High income | E19: 1 | F19: 2039 | G19: 2039 | H19: 2038
A20: Belarus | B20: BLR | C20: EURO | D20: Upper middle income | E20: 2 | F20: 2039 | G20: 2039 | H20: 2037
A21: Belgium | B21: BEL | C21: EURO | D21: High income | E21: 1 | F21: 2030 | G21: 2030 | H21: 2033
A22: Belize | B22: BLZ | C22: PAHO | D22: Upper middle income | E22: 1 | F22: 2040 | G22: 2040 | H22: 2041
A23: Benin | B23: BEN | C23: AFRO | D23: Lower middle income | E23: 3 | F23: 2031 | G23: 2033 | H23: 2033
A24: Bhutan | B24: BTN | C24: SEARO | D24: Lower middle income | E24: 2 | F24: 2041 | G24: 2041 | H24: 2040
A25: Bolivia | B25: BOL | C25: PAHO | D25: Lower middle income | E25: 2 | F25: 2042 | G25: 2042 | H25: 2041
A26: Bosnia and Herzegovina | B26: BIH | C26: EURO | D26: Upper middle income | E26: 1 | F26: 2032 | G26: 2032 | H26: 2031
A27: Botswana | B27: BWA | C27: AFRO | D27: Upper middle income | E27: 2 | F27: 2035 | G27: 2035 | H27: 2037
A28: Brazil | B28: BRA | C28: PAHO | D28: Upper middle income | E28: Key | F28: 2036 | G28: 2036 | H28: 2037
A29: Brunei Darussalam | B29: BRN | C29: WPRO | D29: High income | E29: 1 | F29: 2038 | G29: 2038 | H29: 2040
A30: Bulgaria | B30: BGR | C30: EURO | D30: Upper middle income | E30: 1 | F30: 2034 | G30: 2034 | H30: 2035
A31: Burkina Faso | B31: BFA | C31: AFRO | D31: Low income | E31: 3 | F31: 2033 | G31: 2033 | H31: 2030
A32: Burundi | B32: BDI | C32: AFRO | D32: Low income | E32: 3 | F32: 2033 | G32: 2033 | H32: 2032
A33: Cambodia | B33: KHM | C33: WPRO | D33: Lower middle income | E33: 4 | F33: 2037 | G33: 2037 | H33: 2032
A34: Cameroon | B34: CMR | C34: AFRO | D34: Lower middle income | E34: 3 | F34: 2031 | G34: 2031 | H34: 2032
A35: Canada | B35: CAN | C35: PAHO | D35: High income | E35: 1 | F35: 2033 | G35: 2033 | H35: 2037
A36: Cape Verde | B36: CPV | C36: AFRO | D36: Lower middle income | E36: 2 | F36: 2037 | G36: 2037 | H36: 2034
A37: Central African Republic | B37: CAF | C37: AFRO | D37: Low income | E37: 3 | F37: 2034 | G37: 2034 | H37: 2032
A38: Chad | B38: TCD | C38: AFRO | D38: Low income | E38: Key | F38: 2032 | G38: 2033 | H38: 2031
A39: Chile | B39: CHL | C39: PAHO | D39: High income | E39: 2 | F39: 2035 | G39: 2035 | H39: 2036
A40: China | B40: CHN | C40: WPRO | D40: Upper middle income | E40: 1 | F40: 2030 | G40: 2030 | H40: 2033
A41: Colombia | B41: COL | C41: PAHO | D41: Upper middle income | E41: 2 | F41: 2035 | G41: 2035 | H41: 2037
A42: Comoros | B42: COM | C42: AFRO | D42: Lower middle income | E42: 3 | F42: 2037 | G42: 2037 | H42: 2037
...

Sheet 2a. SI Pop
A1: Title | B1: Surviving infant population
A2: Datasource | B2: UN WPP, Revision 2020
A4: ISO | B4: Country | C4: WHO | D4: WB Group (June 2020) | E4: MR MAP Group | F4: 2030 | G4: 2031 | H4: 2032 | I4: 2033 | J4: 2034 | K4: 2035 | L4: 2036 | M4: 2037 | N4: 2038 | O4: 2039 | P4: 2040
A5: AFG | B5: Afghanistan | C5: EMRO | D5: Low income | E5: Key | F5: 1188620 | G5: 1189745 | H5: 1190653 | I5: 1191186 | J5: 1191145 | K5: 1190375 | L5: 1189083 | M5: 1187078 | N5: 1184391 | O5: 1181096 | P5: 1177251
A6: ALB | B6: Albania | C6: EURO | D6: Upper middle income | E6: 1 | F6: 24693 | G6: 23913 | H6: 23296 | I6: 22812 | J6: 22409 | K6: 22044 | L6: 21728 | M6: 21461 | N6: 21228 | O6: 21016 | P6: 20816
A7: DZA | B7: Algeria | C7: AFRO | D7: Lower middle income | E7: 2 | F7: 827094 | G7: 824587 | H7: 818447 | I7: 810979 | J7: 805702 | K7: 805147 | L7: 810429 | M7: 819806 | N7: 831908 | O7: 844779 | P7: 856887
A8: AND | B8: Andorra | C8: EURO | D8: High income | E8: 1 | F8: 0 | G8: 0 | H8: 0 | I8: 0 | J8: 0 | K8: 0 | L8: 0 | M8: 0 | N8: 0 | O8: 0 | P8: 0
A9: AGO | B9: Angola | C9: AFRO | D9: Lower middle income | E9: 3 | F9: 1555237 | G9: 1589452 | H9: 1624332 | I9: 1659445 | J9: 1694261 | K9: 1728424 | L9: 1761880 | M9: 1794746 | N9: 1827416 | O9: 1860458 | P9: 1894243
A10: ATG | B10: Antigua And Barbuda | C10: PAHO | D10: High income | E10: 1 | F10: 0 | G10: 1343 | H10: 1329 | I10: 1314 | J10: 1300 | K10: 1290 | L10: 1286 | M10: 1285 | N10: 1286 | O10: 1288 | P10: 1286
A11: ARG | B11: Argentina | C11: PAHO | D11: Upper middle income | E11: 1 | F11: 732365 | G11: 729975 | H11: 726782 | I11: 723170 | J11: 719686 | K11: 716725 | L11: 714994 | M11: 713815 | N11: 712855 | O11: 711626 | P11: 709779
A12: ARM | B12: Armenia | C12: EURO | D12: Upper middle income | E12: 1 | F12: 30803 | G12: 30524 | H12: 30339 | I12: 30243 | J12: 30230 | K12: 30286 | L12: 30429 | M12: 30627 | N12: 30851 | O12: 31067 | P12: 31252
A13: AUS | B13: Australia | C13: WPRO | D13: High income | E13: 1 | F13: 323745 | G13: 325024 | H13: 325423 | I13: 325321 | J13: 325323 | K13: 325870 | L13: 327603 | M13: 329798 | N13: 332358 | O13: 335119 | P13: 337937
A14: AUT | B14: Austria | C14: EURO | D14: High income | E14: 1 | F14: 85493 | G14: 84856 | H14: 84075 | I14: 83213 | J14: 82361 | K14: 81586 | L14: 80991 | M14: 80482 | N14: 80067 | O14: 79753 | P14: 79537
A15: AZE | B15: Azerbaijan | C15: EURO | D15: Upper middle income | E15: 1 | F15: 129428 | G15: 129941 | H15: 130678 | I15: 131469 | J15: 132108 | K15: 132444 | L15: 132548 | M15: 132342 | N15: 131803 | O15: 130942 | P15: 129789
A16: BHS | B16: Bahamas | C16: PAHO | D16: High income | E16: 1 | F16: 5456 | G16: 5453 | H16: 5419 | I16: 5366 | J16: 5308 | K16: 5260 | L16: 5229 | M16: 5205 | N16: 5186 | O16: 5168 | P16: 5154
A17: BHR | B17: Bahrain | C17: EMRO | D17: High income | E17: 1 | F17: 22046 | G17: 22039 | H17: 22165 | I17: 22338 | J17: 22430 | K17: 22349 | L17: 22103 | M17: 21705 | N17: 21221 | O17: 20757 | P17: 20383
A18: BGD | B18: Bangladesh | C18: SEARO | D18: Lower middle income | E18: Key | F18: 2519983 | G18: 2489305 | H18: 2461323 | I18: 2434900 | J18: 2408279 | K18: 2380187 | L18: 2351571 | M18: 2321684 | N18: 2291321 | O18: 2261668 | P18: 2233581
A19: BRB | B19: Barbados | C19: PAHO | D19: High income | E19: 1 | F19: 2986 | G19: 2979 | H19: 2965 | I19: 2946 | J19: 2921 | K19: 2893 | L19: 2867 | M19: 2837 | N19: 2804 | O19: 2770 | P19: 2735
A20: BLR | B20: Belarus | C20: EURO | D20: Upper middle income | E20: 2 | F20: 84094 | G20: 82300 | H20: 82058 | I20: 82937 | J20: 84226 | K20: 85388 | L20: 86354 | M20: 87259 | N20: 88133 | O20: 89059 | P20: 90087
A21: BEL | B21: Belgium | C21: EURO | D21: High income | E21: 1 | F21: 118972 | G21: 118666 | H21: 118778 | I21: 119184 | J21: 119682 | K21: 120118 | L21: 120636 | M21: 121103 | N21: 121512 | O21: 121874 | P21: 122194
A22: BLZ | B22: Belize | C22: PAHO | D22: Upper middle income | E22: 1 | F22: 7893 | G22: 7851 | H22: 7825 | I22: 7808 | J22: 7790 | K22: 7763 | L22: 7732 | M22: 7695 | N22: 7652 | O22: 7607 | P22: 7563
A23: BEN | B23: Benin | C23: AFRO | D23: Lower middle income | E23: 3 | F23: 476522 | G23: 483712 | H23: 490943 | I23: 498170 | J23: 505346 | K23: 512433 | L23: 519389 | M23: 526292 | N23: 533105 | O23: 539789 | P23: 546320
A24: BTN | B24: Bhutan | C24: SEARO | D24: Lower middle income | E24: 2 | F24: 10939 | G24: 10783 | H24: 10587 | I24: 10364 | J24: 10140 | K24: 9932 | L24: 9751 | M24: 9584 | N24: 9433 | O24: 9298 | P24: 9182
A25: BOL | B25: Bolivia | C25: PAHO | D25: Lower middle income | E25: 2 | F25: 241987 | G25: 241232 | H25: 240667 | I25: 240236 | J25: 239843 | K25: 239404 | L25: 239055 | M25: 238700 | N25: 238269 | O25: 237666 | P25: 236828
A26: BIH | B26: Bosnia and Herzegovina | C26: EURO | D26: Upper middle income | E26: 1 | F26: 22287 | G26: 22126 | H26: 22121 | I26: 22211 | J26: 22307 | K26: 22338 | L26: 22304 | M26: 22209 | N26: 22064 | O26: 21894 | P26: 21721
A27: BWA | B27: Botswana | C27: AFRO | D27: Upper middle income | E27: 2 | F27: 54304 | G27: 54525 | H27: 54671 | I27: 54764 | J27: 54841 | K27: 54932 | L27: 55084 | M27: 55244 | N27: 55384 | O27: 55472 | P27: 55484
A28: BRA | B28: Brazil | C28: PAHO | D28: Upper middle income | E28: Key | F28: 2511946 | G28: 2492137 | H28: 2469079 | I28: 2443271 | J28: 2415734 | K28: 2387322 | L28: 2359889 | M28: 2331427 | N28: 2302988 | O28: 2276043 | P28: 2251652
A29: BRN | B29: Brunei Darussalam | C29: WPRO | D29: High income | E29: 1 | F29: 5395 | G29: 5302 | H29: 5241 | I29: 5203 | J29: 5174 | K29: 5144 | L29: 5120 | M29: 5096 | N29: 5075 | O29: 5055 | P29: 5038
A30: BGR | B30: Bulgaria | C30: EURO | D30: Upper middle income | E30: 1 | F30: 53902 | G30: 53523 | H30: 53152 | I30: 52807 | J30: 52523 | K30: 52323 | L30: 52201 | M30: 52141 | N30: 52113 | O30: 52076 | P30: 52000
A31: BFA | B31: Burkina Faso | C31: AFRO | D31: Low income | E31: 3 | F31: 870205 | G31: 883882 | H31: 897219 | I31: 910230 | J31: 922990 | K31: 935560 | L31: 947949 | M31: 960172 | N31: 972123 | O31: 983684 | P31: 994772
A32: BDI | B32: Burundi | C32: AFRO | D32: Low income | E32: 3 | F32: 496204 | G32: 503605 | H32: 511504 | I32: 519761 | J32: 528170 | K32: 536560 | L32: 544889 | M32: 553209 | N32: 561491 | O32: 569716 | P32: 577868
A33: KHM | B33: Cambodia | C33: WPRO | D33: Lower middle income | E33: 4 | F33: 332712 | G33: 333107 | H33: 333741 | I33: 334463 | J33: 335085 | K33: 335455 | L33: 335658 | M33: 335579 | N33: 335117 | O33: 334183 | P33: 332730
A34: CMR | B34: Cameroon | C34: AFRO | D34: Lower middle income | E34: 3 | F34: 983852 | G34: 995597 | H34: 1007108 | I34: 1018497 | J34: 1029958 | K34: 1041622 | L34: 1053642 | M34: 1065898 | N34: 1078180 | O34: 1090203 | P34: 1101755
A35: CAN | B35: Canada | C35: PAHO | D35: High income | E35: 1 | F35: 399804 | G35: 400929 | H35: 401429 | I35: 401606 | J35: 401913 | K35: 402674 | L35: 404716 | M35: 407165 | N35: 409873 | O35: 412608 | P35: 415183
A36: CPV | B36: Cape Verde | C36: AFRO | D36: Lower middle income | E36: 2 | F36: 9099 | G36: 9012 | H36: 8949 | I36: 8905 | J36: 8862 | K36: 8812 | L36: 8757 | M36: 8695 | N36: 8628 | O36: 8562 | P36: 8498
A37: CAF | B37: Central African Republic | C37: AFRO | D37: Low income | E37: 3 | F37: 179226 | G37: 180243 | H37: 181264 | I37: 182221 | J37: 183028 | K37: 183621 | L37: 183956 | M37: 184121 | N37: 184166 | O37: 184158 | P37: 184147
A38: TCD | B38: Chad | C38: AFRO | D38: Low income | E38: Key | F38: 733710 | G38: 743419 | H38: 753198 | I38: 762912 | J38: 772393 | K38: 781523 | L38: 789749 | M38: 797706 | N38: 805515 | O38: 813357 | P38: 821350
A39: CHL | B39: Chile | C39: PAHO | D39: High income | E39: 2 | F39: 200425 | G39: 198508 | H39: 198456 | I39: 199500 | J39: 200482 | K39: 200561 | L39: 199757 | M39: 198127 | N39: 196040 | O39: 194078 | P39: 192649
A40: CHN | B40: China | C40: WPRO | D40: Upper middle income | E40: 1 | F40: 14139260 | G40: 14077286 | H40: 13997268 | I40: 13904630 | J40: 13809850 | K40: 13720911 | L40: 13652009 | M40: 13585091 | N40: 13521676 | O40: 13464045 | P40: 13413139
A41: COL | B41: Colombia | C41: PAHO | D41: Upper middle income | E41: 2 | F41: 640771 | G41: 636441 | H41: 630342 | I41: 622977 | J41: 615227 | K41: 607761 | L41: 601141 | M41: 594633 | N41: 588324 | O41: 582310 | P41: 576653
...

Sheet 2b. 2 yr pop
A1: Title | B1: two year old population
A2: Datasource | B2: UN WPP, Revision 2020
A4: ISO | B4: Country | C4: WHO | D4: WB Group (June 2020) | E4: MR MAP Group | F4: 2030 | G4: 2031 | H4: 2032 | I4: 2033 | J4: 2034 | K4: 2035 | L4: 2036 | M4: 2037 | N4: 2038 | O4: 2039 | P4: 2040
A5: AFG | B5: Afghanistan | C5: EMRO | D5: Low income | E5: Key | F5: 1183547 | G5: 1185914 | H5: 1186114 | I5: 1186833 | J5: 1187037 | K5: 1186634 | L5: 1187735 | M5: 1184529 | N5: 1182605 | O5: 1180085 | P5: 1176967
A6: ALB | B6: Albania | C6: EURO | D6: Upper middle income | E6: 1 | F6: 25632 | G6: 24651 | H6: 24059 | I6: 23393 | J6: 22800 | K6: 22272 | L6: 21904 | M6: 21450 | N6: 21136 | O6: 20866 | P6: 20627
A7: DZA | B7: Algeria | C7: AFRO | D7: Lower middle income | E7: 2 | F7: 819737 | G7: 821951 | H7: 804455 | I7: 798985 | J7: 796091 | K7: 796422 | L7: 803616 | M7: 807869 | N7: 817243 | O7: 827840 | P7: 838840
A8: AND | B8: Andorra | C8: EURO | D8: High income | E8: 1 | F8: 0 | G8: 0 | H8: 0 | I8: 0 | J8: 0 | K8: 0 | L8: 0 | M8: 0 | N8: 0 | O8: 0 | P8: 0
A9: AGO | B9: Angola | C9: AFRO | D9: Lower middle income | E9: 3 | F9: 1512448 | G9: 1550187 | H9: 1582713 | I9: 1618066 | J9: 1653162 | K9: 1687792 | L9: 1723970 | M9: 1755650 | N9: 1789112 | O9: 1822667 | P9: 1856534
A10: ATG | B10: Antigua And Barbuda | C10: PAHO | D10: High income | E10: 1 | F10: 0 | G10: 1351 | H10: 1331 | I10: 1319 | J10: 1309 | K10: 1300 | L10: 1291 | M10: 1290 | N10: 1288 | O10: 1286 | P10: 1283
A11: ARG | B11: Argentina | C11: PAHO | D11: Upper middle income | E11: 1 | F11: 732108 | G11: 731819 | H11: 727681 | I11: 724976 | J11: 722248 | K11: 719676 | L11: 717038 | M11: 716248 | N11: 714652 | O11: 712877 | P11: 710767
A12: ARM | B12: Armenia | C12: EURO | D12: Upper middle income | E12: 1 | F12: 31006 | G12: 30697 | H12: 30231 | I12: 30015 | J12: 29898 | K12: 29870 | L12: 30165 | M12: 30098 | N12: 30299 | O12: 30519 | P12: 30732
A13: AUS | B13: Australia | C13: WPRO | D13: High income | E13: 1 | F13: 324108 | G13: 326042 | H13: 325016 | I13: 325444 | J13: 326028 | K13: 326876 | L13: 328776 | M13: 330523 | N13: 332695 | O13: 335051 | P13: 337539
A14: AUT | B14: Austria | C14: EURO | D14: High income | E14: 1 | F14: 86816 | G14: 85818 | H14: 85251 | I14: 84399 | J14: 83550 | K14: 82736 | L14: 81891 | M14: 81443 | N14: 80899 | O14: 80443 | P14: 80081
A15: AZE | B15: Azerbaijan | C15: EURO | D15: Upper middle income | E15: 1 | F15: 126828 | G15: 128566 | H15: 127212 | I15: 127973 | J15: 128808 | K15: 129531 | L15: 131868 | M15: 130713 | N15: 130981 | O15: 130931 | P15: 130525
A16: BHS | B16: Bahamas | C16: PAHO | D16: High income | E16: 1 | F16: 5478 | G16: 5464 | H16: 5441 | I16: 5406 | J16: 5367 | K16: 5329 | L16: 5278 | M16: 5271 | N16: 5243 | O16: 5216 | P16: 5192
A17: BHR | B17: Bahrain | C17: EMRO | D17: High income | E17: 1 | F17: 22264 | G17: 22155 | H17: 22389 | I17: 22453 | J17: 22451 | K17: 22350 | L17: 22333 | M17: 21903 | N17: 21575 | O17: 21238 | P17: 20927
A18: BGD | B18: Bangladesh | C18: SEARO | D18: Lower middle income | E18: Key | F18: 2558646 | G18: 2520285 | H18: 2494231 | I18: 2463353 | J18: 2432648 | K18: 2401657 | L18: 2377055 | M18: 2341692 | N18: 2311988 | O18: 2282959 | P18: 2254898
A19: BRB | B19: Barbados | C19: PAHO | D19: High income | E19: 1 | F19: 2992 | G19: 2985 | H19: 2975 | I19: 2960 | J19: 2940 | K19: 2918 | L19: 2894 | M19: 2869 | N19: 2839 | O19: 2806 | P19: 2772
A20: BLR | B20: Belarus | C20: EURO | D20: Upper middle income | E20: 2 | F20: 88008 | G20: 84725 | H20: 85160 | I20: 84610 | J20: 84440 | K20: 84502 | L20: 85178 | M20: 85350 | N20: 86105 | O20: 87032 | P20: 88088
A21: BEL | B21: Belgium | C21: EURO | D21: High income | E21: 1 | F21: 120670 | G21: 119771 | H21: 120220 | I21: 120206 | J21: 120275 | K21: 120380 | L21: 120673 | M21: 121039 | N21: 121407 | O21: 121770 | P21: 122110
A22: BLZ | B22: Belize | C22: PAHO | D22: Upper middle income | E22: 1 | F22: 8011 | G22: 7921 | H22: 7938 | I22: 7900 | J22: 7861 | K22: 7817 | L22: 7770 | M22: 7736 | N22: 7693 | O22: 7648 | P22: 7604
A23: BEN | B23: Benin | C23: AFRO | D23: Lower middle income | E23: 3 | F23: 465609 | G23: 473956 | H23: 480337 | I23: 487677 | J23: 494962 | K23: 502166 | L23: 510039 | M23: 516267 | N23: 523201 | O23: 530016 | P23: 536688
A24: BTN | B24: Bhutan | C24: SEARO | D24: Lower middle income | E24: 2 | F24: 11099 | G24: 10921 | H24: 10704 | I24: 10495 | J24: 10289 | K24: 10089 | L24: 9921 | M24: 9730 | N24: 9565 | O24: 9415 | P24: 9280
A25: BOL | B25: Bolivia | C25: PAHO | D25: Lower middle income | E25: 2 | F25: 242262 | G25: 241673 | H25: 241433 | I25: 240911 | J25: 240347 | K25: 239752 | L25: 239044 | M25: 238767 | N25: 238214 | O25: 237546 | P25: 236720
A26: BIH | B26: Bosnia and Herzegovina | C26: EURO | D26: Upper middle income | E26: 1 | F26: 22564 | G26: 22334 | H26: 22391 | I26: 22373 | J26: 22361 | K26: 22330 | L26: 22323 | M26: 22216 | N26: 22123 | O26: 22009 | P26: 21879
A27: BWA | B27: Botswana | C27: AFRO | D27: Upper middle income | E27: 2 | F27: 53647 | G27: 54159 | H27: 54050 | I27: 54244 | J27: 54433 | K27: 54616 | L27: 54901 | M27: 55039 | N27: 55214 | O27: 55340 | P27: 55404
A28: BRA | B28: Brazil | C28: PAHO | D28: Upper middle income | E28: Key | F28: 2530235 | G28: 2508994 | H28: 2478921 | I28: 2453720 | J28: 2428155 | K28: 2401870 | L28: 2385047 | M28: 2351032 | N28: 2325243 | O28: 2300149 | P28: 2276349
A29: BRN | B29: Brunei Darussalam | C29: WPRO | D29: High income | E29: 1 | F29: 5472 | G29: 5400 | H29: 5340 | I29: 5285 | J29: 5236 | K29: 5190 | L29: 5147 | M29: 5122 | N29: 5093 | O29: 5067 | P29: 5044
A30: BGR | B30: Bulgaria | C30: EURO | D30: Upper middle income | E30: 1 | F30: 54316 | G30: 53840 | H30: 53390 | I30: 52996 | J30: 52665 | K30: 52407 | L30: 52240 | M30: 52080 | N30: 51989 | O30: 51911 | P30: 51827
A31: BFA | B31: Burkina Faso | C31: AFRO | D31: Low income | E31: 3 | F31: 850055 | G31: 866395 | H31: 878037 | I31: 891776 | J31: 905278 | K31: 918515 | L31: 932601 | M31: 944157 | N31: 956525 | O31: 968498 | P31: 980030
A32: BDI | B32: Burundi | C32: AFRO | D32: Low income | E32: 3 | F32: 487338 | G32: 494722 | H32: 502195 | I32: 510005 | J32: 517992 | K32: 526088 | L32: 534946 | M32: 542562 | N32: 550906 | O32: 559254 | P32: 567557
A33: KHM | B33: Cambodia | C33: WPRO | D33: Lower middle income | E33: 4 | F33: 331972 | G33: 332024 | H33: 331588 | I33: 331873 | J33: 332262 | K33: 332610 | L33: 334532 | M33: 333352 | N33: 333476 | O33: 333231 | P33: 332515
A34: CMR | B34: Cameroon | C34: AFRO | D34: Lower middle income | E34: 3 | F34: 964326 | G34: 979204 | H34: 988776 | I34: 1000830 | J34: 1012851 | K34: 1024895 | L34: 1037872 | M34: 1049257 | N34: 1061381 | O34: 1073300 | P34: 1084910
A35: CAN | B35: Canada | C35: PAHO | D35: High income | E35: 1 | F35: 402569 | G35: 402321 | H35: 404216 | I35: 404813 | J35: 405472 | K35: 406320 | L35: 405675 | M35: 410145 | N35: 412281 | O35: 414473 | P35: 416648
A36: CPV | B36: Cape Verde | C36: AFRO | D36: Lower middle income | E36: 2 | F36: 9141 | G36: 9071 | H36: 8971 | I36: 8904 | J36: 8843 | K36: 8783 | L36: 8780 | M36: 8668 | N36: 8613 | O36: 8558 | P36: 8503
A37: CAF | B37: Central African Republic | C37: AFRO | D37: Low income | E37: 3 | F37: 176084 | G37: 178091 | H37: 179136 | I37: 180352 | J37: 181346 | K37: 182121 | L37: 182645 | M37: 182946 | N37: 183105 | O37: 183165 | P37: 183173
A38: TCD | B38: Chad | C38: AFRO | D38: Low income | E38: Key | F38: 716015 | G38: 727536 | H38: 735903 | I38: 745754 | J38: 755409 | K38: 764789 | L38: 775388 | M38: 781782 | N38: 790051 | O38: 798275 | P38: 806510
A39: CHL | B39: Chile | C39: PAHO | D39: High income | E39: 2 | F39: 204806 | G39: 201240 | H39: 202142 | I39: 201766 | J39: 201409 | K39: 200696 | L39: 200579 | M39: 198519 | N39: 197079 | O39: 195694 | P39: 194534
A40: CHN | B40: China | C40: WPRO | D40: Upper middle income | E40: 1 | F40: 14092832 | G40: 14094897 | H40: 13909190 | I40: 13832828 | J40: 13762495 | K40: 13695845 | L40: 13704055 | M40: 13596110 | N40: 13547668 | O40: 13501572 | P40: 13458309
A41: COL | B41: Colombia | C41: PAHO | D41: Upper middle income | E41: 2 | F41: 644209 | G41: 639623 | H41: 631340 | I41: 624714 | J41: 618063 | K41: 611467 | L41: 607186 | M41: 599425 | N41: 593477 | O41: 587674 | P41: 582070
...

Sheet 2c. U2 pop
A1: Title | B1: U2 year population
A2: Datasource | B2: UN WPP, Revision 2020
A4: ISO | B4: Country | C4: WHO | D4: WB Group (June 2020) | E4: MR MAP Group | F4: 2030 | G4: 2031 | H4: 2032 | I4: 2033 | J4: 2034 | K4: 2035 | L4: 2036 | M4: 2037 | N4: 2038 | O4: 2039 | P4: 2040
A5: AFG | B5: Afghanistan | C5: EMRO | D5: Low income | E5: Key | F5: 2372167 | G5: 2375659 | H5: 2376767 | I5: 2378019 | J5: 2378182 | K5: 2377009 | L5: 2376818 | M5: 2371607 | N5: 2366996 | O5: 2361181 | P5: 2354218
A6: ALB | B6: Albania | C6: EURO | D6: Upper middle income | E6: 1 | F6: 50325 | G6: 48564 | H6: 47355 | I6: 46205 | J6: 45209 | K6: 44316 | L6: 43632 | M6: 42911 | N6: 42364 | O6: 41882 | P6: 41443
A7: DZA | B7: Algeria | C7: AFRO | D7: Lower middle income | E7: 2 | F7: 1646831 | G7: 1646538 | H7: 1622902 | I7: 1609964 | J7: 1601793 | K7: 1601569 | L7: 1614045 | M7: 1627675 | N7: 1649151 | O7: 1672619 | P7: 1695727
A8: AND | B8: Andorra | C8: EURO | D8: High income | E8: 1 | F8: 0 | G8: 0 | H8: 0 | I8: 0 | J8: 0 | K8: 0 | L8: 0 | M8: 0 | N8: 0 | O8: 0 | P8: 0
A9: AGO | B9: Angola | C9: AFRO | D9: Lower middle income | E9: 3 | F9: 3067685 | G9: 3139639 | H9: 3207045 | I9: 3277511 | J9: 3347423 | K9: 3416216 | L9: 3485850 | M9: 3550396 | N9: 3616528 | O9: 3683125 | P9: 3750777
A10: ATG | B10: Antigua And Barbuda | C10: PAHO | D10: High income | E10: 1 | F10: 0 | G10: 2694 | H10: 2660 | I10: 2633 | J10: 2609 | K10: 2590 | L10: 2577 | M10: 2575 | N10: 2574 | O10: 2574 | P10: 2569
A11: ARG | B11: Argentina | C11: PAHO | D11: Upper middle income | E11: 1 | F11: 1464473 | G11: 1461794 | H11: 1454463 | I11: 1448146 | J11: 1441934 | K11: 1436401 | L11: 1432032 | M11: 1430063 | N11: 1427507 | O11: 1424503 | P11: 1420546
A12: ARM | B12: Armenia | C12: EURO | D12: Upper middle income | E12: 1 | F12: 61809 | G12: 61221 | H12: 60570 | I12: 60258 | J12: 60128 | K12: 60156 | L12: 60594 | M12: 60725 | N12: 61150 | O12: 61586 | P12: 61984
A13: AUS | B13: Australia | C13: WPRO | D13: High income | E13: 1 | F13: 647853 | G13: 651066 | H13: 650439 | I13: 650765 | J13: 651351 | K13: 652746 | L13: 656379 | M13: 660321 | N13: 665053 | O13: 670170 | P13: 675476
A14: AUT | B14: Austria | C14: EURO | D14: High income | E14: 1 | F14: 172309 | G14: 170674 | H14: 169326 | I14: 167612 | J14: 165911 | K14: 164322 | L14: 162882 | M14: 161925 | N14: 160966 | O14: 160196 | P14: 159618
A15: AZE | B15: Azerbaijan | C15: EURO | D15: Upper middle income | E15: 1 | F15: 256256 | G15: 258507 | H15: 257890 | I15: 259442 | J15: 260916 | K15: 261975 | L15: 264416 | M15: 263055 | N15: 262784 | O15: 261873 | P15: 260314
A16: BHS | B16: Bahamas | C16: PAHO | D16: High income | E16: 1 | F16: 10934 | G16: 10917 | H16: 10860 | I16: 10772 | J16: 10675 | K16: 10589 | L16: 10507 | M16: 10476 | N16: 10429 | O16: 10384 | P16: 10346
A17: BHR | B17: Bahrain | C17: EMRO | D17: High income | E17: 1 | F17: 44310 | G17: 44194 | H17: 44554 | I17: 44791 | J17: 44881 | K17: 44699 | L17: 44436 | M17: 43608 | N17: 42796 | O17: 41995 | P17: 41310
A18: BGD | B18: Bangladesh | C18: SEARO | D18: Lower middle income | E18: Key | F18: 5078629 | G18: 5009590 | H18: 4955554 | I18: 4898253 | J18: 4840927 | K18: 4781844 | L18: 4728626 | M18: 4663376 | N18: 4603309 | O18: 4544627 | P18: 4488479
A19: BRB | B19: Barbados | C19: PAHO | D19: High income | E19: 1 | F19: 5978 | G19: 5964 | H19: 5940 | I19: 5906 | J19: 5861 | K19: 5811 | L19: 5761 | M19: 5706 | N19: 5643 | O19: 5576 | P19: 5507
A20: BLR | B20: Belarus | C20: EURO | D20: Upper middle income | E20: 2 | F20: 172102 | G20: 167025 | H20: 167218 | I20: 167547 | J20: 168666 | K20: 169890 | L20: 171532 | M20: 172609 | N20: 174238 | O20: 176091 | P20: 178175
A21: BEL | B21: Belgium | C21: EURO | D21: High income | E21: 1 | F21: 239642 | G21: 238437 | H21: 238998 | I21: 239390 | J21: 239957 | K21: 240498 | L21: 241309 | M21: 242142 | N21: 242919 | O21: 243644 | P21: 244304
A22: BLZ | B22: Belize | C22: PAHO | D22: Upper middle income | E22: 1 | F22: 15904 | G22: 15772 | H22: 15763 | I22: 15708 | J22: 15651 | K22: 15580 | L22: 15502 | M22: 15431 | N22: 15345 | O22: 15255 | P22: 15167
A23: BEN | B23: Benin | C23: AFRO | D23: Lower middle income | E23: 3 | F23: 942131 | G23: 957668 | H23: 971280 | I23: 985847 | J23: 1000308 | K23: 1014599 | L23: 1029428 | M23: 1042559 | N23: 1056306 | O23: 1069805 | P23: 1083008
A24: BTN | B24: Bhutan | C24: SEARO | D24: Lower middle income | E24: 2 | F24: 22038 | G24: 21704 | H24: 21291 | I24: 20859 | J24: 20429 | K24: 20021 | L24: 19672 | M24: 19314 | N24: 18998 | O24: 18713 | P24: 18462
A25: BOL | B25: Bolivia | C25: PAHO | D25: Lower middle income | E25: 2 | F25: 484249 | G25: 482905 | H25: 482100 | I25: 481147 | J25: 480190 | K25: 479156 | L25: 478099 | M25: 477467 | N25: 476483 | O25: 475212 | P25: 473548
A26: BIH | B26: Bosnia and Herzegovina | C26: EURO | D26: Upper middle income | E26: 1 | F26: 44851 | G26: 44460 | H26: 44512 | I26: 44584 | J26: 44668 | K26: 44668 | L26: 44627 | M26: 44425 | N26: 44187 | O26: 43903 | P26: 43600
A27: BWA | B27: Botswana | C27: AFRO | D27: Upper middle income | E27: 2 | F27: 107951 | G27: 108684 | H27: 108721 | I27: 109008 | J27: 109274 | K27: 109548 | L27: 109985 | M27: 110283 | N27: 110598 | O27: 110812 | P27: 110888
A28: BRA | B28: Brazil | C28: PAHO | D28: Upper middle income | E28: Key | F28: 5042181 | G28: 5001131 | H28: 4948000 | I28: 4896991 | J28: 4843889 | K28: 4789192 | L28: 4744936 | M28: 4682459 | N28: 4628231 | O28: 4576192 | P28: 4528001
A29: BRN | B29: Brunei Darussalam | C29: WPRO | D29: High income | E29: 1 | F29: 10867 | G29: 10702 | H29: 10581 | I29: 10488 | J29: 10410 | K29: 10334 | L29: 10267 | M29: 10218 | N29: 10168 | O29: 10122 | P29: 10082
A30: BGR | B30: Bulgaria | C30: EURO | D30: Upper middle income | E30: 1 | F30: 108218 | G30: 107363 | H30: 106542 | I30: 105803 | J30: 105188 | K30: 104730 | L30: 104441 | M30: 104221 | N30: 104102 | O30: 103987 | P30: 103827
A31: BFA | B31: Burkina Faso | C31: AFRO | D31: Low income | E31: 3 | F31: 1720260 | G31: 1750277 | H31: 1775256 | I31: 1802006 | J31: 1828268 | K31: 1854075 | L31: 1880550 | M31: 1904329 | N31: 1928648 | O31: 1952182 | P31: 1974802
A32: BDI | B32: Burundi | C32: AFRO | D32: Low income | E32: 3 | F32: 983542 | G32: 998327 | H32: 1013699 | I32: 1029766 | J32: 1046162 | K32: 1062648 | L32: 1079835 | M32: 1095771 | N32: 1112397 | O32: 1128970 | P32: 1145425
A33: KHM | B33: Cambodia | C33: WPRO | D33: Lower middle income | E33: 4 | F33: 664684 | G33: 665131 | H33: 665329 | I33: 666336 | J33: 667347 | K33: 668065 | L33: 670190 | M33: 668931 | N33: 668593 | O33: 667414 | P33: 665245
A34: CMR | B34: Cameroon | C34: AFRO | D34: Lower middle income | E34: 3 | F34: 1948178 | G34: 1974801 | H34: 1995884 | I34: 2019327 | J34: 2042809 | K34: 2066517 | L34: 2091514 | M34: 2115155 | N34: 2139561 | O34: 2163503 | P34: 2186665
A35: CAN | B35: Canada | C35: PAHO | D35: High income | E35: 1 | F35: 802373 | G35: 803250 | H35: 805645 | I35: 806419 | J35: 807385 | K35: 808994 | L35: 810391 | M35: 817310 | N35: 822154 | O35: 827081 | P35: 831831
A36: CPV | B36: Cape Verde | C36: AFRO | D36: Lower middle income | E36: 2 | F36: 18240 | G36: 18083 | H36: 17920 | I36: 17809 | J36: 17705 | K36: 17595 | L36: 17537 | M36: 17363 | N36: 17241 | O36: 17120 | P36: 17001
A37: CAF | B37: Central African Republic | C37: AFRO | D37: Low income | E37: 3 | F37: 355310 | G37: 358334 | H37: 360400 | I37: 362573 | J37: 364374 | K37: 365742 | L37: 366601 | M37: 367067 | N37: 367271 | O37: 367323 | P37: 367320
A38: TCD | B38: Chad | C38: AFRO | D38: Low income | E38: Key | F38: 1449725 | G38: 1470955 | H38: 1489101 | I38: 1508666 | J38: 1527802 | K38: 1546312 | L38: 1565137 | M38: 1579488 | N38: 1595566 | O38: 1611632 | P38: 1627860
A39: CHL | B39: Chile | C39: PAHO | D39: High income | E39: 2 | F39: 405231 | G39: 399748 | H39: 400598 | I39: 401266 | J39: 401891 | K39: 401257 | L39: 400336 | M39: 396646 | N39: 393119 | O39: 389772 | P39: 387183
A40: CHN | B40: China | C40: WPRO | D40: Upper middle income | E40: 1 | F40: 28232092 | G40: 28172183 | H40: 27906458 | I40: 27737458 | J40: 27572345 | K40: 27416756 | L40: 27356064 | M40: 27181201 | N40: 27069344 | O40: 26965617 | P40: 26871448
A41: COL | B41: Colombia | C41: PAHO | D41: Upper middle income | E41: 2 | F41: 1284980 | G41: 1276064 | H41: 1261682 | I41: 1247691 | J41: 1233290 | K41: 1219228 | L41: 1208327 | M41: 1194058 | N41: 1181801 | O41: 1169984 | P41: 1158723
...

Sheet 2d. U2 pop %
A1: Title | B1: U2 year olds % to total population (65 years of age)
A2: Datasource | B2: UN WPP, Revision 2020
A4: ISO | B4: Country | C4: WHO | D4: WB Group (June 2020) | E4: MR MAP Group | F4: 2030 | G4: 2031 | H4: 2032 | I4: 2033 | J4: 2034 | K4: 2035 | L4: 2036 | M4: 2037 | N4: 2038 | O4: 2039 | P4: 2040
A5: AFG | B5: Afghanistan | C5: EMRO | D5: Low income | E5: Key | F5: 0.050760172 | G5: 0.049926453 | H5: 0.049076451 | I5: 0.048263872 | J5: 0.047463704 | K5: 0.046671664 | L5: 0.045936263 | M5: 0.045135735 | N5: 0.044379232 | O5: 0.043632605 | P5: 0.042897669
A6: ALB | B6: Albania | C6: EURO | D6: Upper middle income | E6: 1 | F6: 0.022405802 | G6: 0.021859754 | H6: 0.021542361 | I6: 0.021236326 | J6: 0.020991239 | K6: 0.020790953 | L6: 0.02067832 | M6: 0.020546256 | N6: 0.020496782 | O6: 0.020476451 | P6: 0.020471401
A7: DZA | B7: Algeria | C7: AFRO | D7: Lower middle income | E7: 2 | F7: 0.035643758 | G7: 0.035347999 | H7: 0.034573496 | I7: 0.034048778 | J7: 0.033640303 | K7: 0.033409491 | L7: 0.033438639 | M7: 0.033495086 | N7: 0.033714685 | O7: 0.033977687 | P7: 0.034239358
A8: AND | B8: Andorra | C8: EURO | D8: High income | E8: 1 | F8: 0 | G8: 0 | H8: 0 | I8: 0 | J8: 0 | K8: 0 | L8: 0 | M8: 0 | N8: 0 | O8: 0 | P8: 0
A9: AGO | B9: Angola | C9: AFRO | D9: Lower middle income | E9: 3 | F9: 0.069983618 | G9: 0.069532671 | H9: 0.068957937 | I9: 0.068431554 | J9: 0.067883038 | K9: 0.067310922 | L9: 0.066765331 | M9: 0.066125702 | N9: 0.065521749 | O9: 0.064929933 | P9: 0.064358024
A10: ATG | B10: Antigua And Barbuda | C10: PAHO | D10: High income | E10: 1 | F10: 0 | G10: 0.029388343 | H10: 0.029040887 | I10: 0.028779731 | J10: 0.028558606 | K10: 0.028396321 | L10: 0.028295982 | M10: 0.028311948 | N10: 0.028343335 | O10: 0.028388036 | P10: 0.028381723
A11: ARG | B11: Argentina | C11: PAHO | D11: Upper middle income | E11: 1 | F11: 0.033897201 | G11: 0.033645788 | H11: 0.033293889 | I11: 0.032973101 | J11: 0.032664361 | K11: 0.032383114 | L11: 0.032139859 | M11: 0.03196004 | N11: 0.031776543 | O11: 0.031595765 | P11: 0.031410666
A12: ARM | B12: Armenia | C12: EURO | D12: Upper middle income | E12: 1 | F12: 0.024735156 | G12: 0.024639142 | H12: 0.024497888 | I12: 0.024473842 | J12: 0.024509808 | K12: 0.024605603 | L12: 0.024865983 | M12: 0.02499929 | N12: 0.025254841 | O12: 0.025519276 | P12: 0.025774859
A13: AUS | B13: Australia | C13: WPRO | D13: High income | E13: 1 | F13: 0.028128765 | G13: 0.02809841 | H13: 0.027902137 | I13: 0.027747494 | J13: 0.027608627 | K13: 0.027514815 | L13: 0.027504885 | M13: 0.027516671 | N13: 0.027571439 | O13: 0.027647845 | P13: 0.027731068
A14: AUT | B14: Austria | C14: EURO | D14: High income | E14: 1 | F14: 0.024141758 | G14: 0.024054776 | H14: 0.02401166 | I14: 0.023920705 | J14: 0.023830299 | K14: 0.023747735 | L14: 0.023663304 | M14: 0.023633125 | N14: 0.023587696 | O14: 0.023559022 | P14: 0.023554199
A15: AZE | B15: Azerbaijan | C15: EURO | D15: Upper middle income | E15: 1 | F15: 0.026719382 | G15: 0.026996082 | H15: 0.026963571 | I15: 0.027148857 | J15: 0.02731984 | K15: 0.027445027 | L15: 0.02770431 | M15: 0.027562519 | N15: 0.027534638 | O15: 0.0274424 | P15: 0.027287447
A16: BHS | B16: Bahamas | C16: PAHO | D16: High income | E16: 1 | F16: 0.028708109 | G16: 0.028606092 | H16: 0.028400399 | I16: 0.028115123 | J16: 0.027813168 | K16: 0.027551772 | L16: 0.027314605 | M16: 0.027220783 | N16: 0.027097673 | O16: 0.026986779 | P16: 0.026893753
A17: BHR | B17: Bahrain | C17: EMRO | D17: High income | E17: 1 | F17: 0.023163153 | G17: 0.022897864 | H17: 0.022909238 | I17: 0.022881912 | J17: 0.022799478 | K17: 0.02259536 | L17: 0.022359896 | M17: 0.021857332 | N17: 0.021380393 | O17: 0.02092463 | P17: 0.020540538
A18: BGD | B18: Bangladesh | C18: SEARO | D18: Lower middle income | E18: Key | F18: 0.030421679 | G18: 0.029917565 | H18: 0.029517293 | I18: 0.02911216 | J18: 0.028720314 | K18: 0.028329593 | L18: 0.027985016 | M18: 0.027577707 | N18: 0.027209413 | O18: 0.026859558 | P18: 0.02653777
A19: BRB | B19: Barbados | C19: PAHO | D19: High income | E19: 1 | F19: 0.026070081 | G19: 0.026158239 | H19: 0.026196945 | I19: 0.026184765 | J19: 0.026122496 | K19: 0.026047316 | L19: 0.025963432 | M19: 0.02586629 | N19: 0.025744905 | O19: 0.025609935 | P19: 0.02546672
A20: BLR | B20: Belarus | C20: EURO | D20: Upper middle income | E20: 2 | F20: 0.022984297 | G20: 0.022493538 | H20: 0.022676579 | I20: 0.022846363 | J20: 0.023105343 | K20: 0.023379881 | L20: 0.023730677 | M20: 0.024010709 | N20: 0.0243761 | O20: 0.024778627 | P20: 0.025213492
A21: BEL | B21: Belgium | C21: EURO | D21: High income | E21: 1 | F21: 0.025706193 | G21: 0.025639807 | H21: 0.025759624 | I21: 0.025859016 | J21: 0.025976904 | K21: 0.026093359 | L21: 0.026220085 | M21: 0.02634694 | N21: 0.026466977 | O21: 0.026581922 | P21: 0.026691679
A22: BLZ | B22: Belize | C22: PAHO | D22: Upper middle income | E22: 1 | F22: 0.036357734 | G22: 0.03565704 | H22: 0.035258618 | I22: 0.034779451 | J22: 0.034318605 | K22: 0.033852492 | L22: 0.033388687 | M22: 0.032962503 | N22: 0.032526443 | O22: 0.032101327 | P22: 0.031697433
A23: BEN | B23: Benin | C23: AFRO | D23: Lower middle income | E23: 3 | F23: 0.062140913 | G23: 0.061672518 | H23: 0.061084964 | I23: 0.060565281 | J23: 0.060046541 | K23: 0.059526108 | L23: 0.059047732 | M23: 0.058479916 | N23: 0.057957364 | O23: 0.057432781 | P23: 0.056905796
A24: BTN | B24: Bhutan | C24: SEARO | D24: Lower middle income | E24: 2 | F24: 0.028191247 | G24: 0.027643196 | H24: 0.027016156 | I24: 0.026386329 | J24: 0.025778081 | K24: 0.025211269 | L24: 0.024729909 | M24: 0.0242474 | N24: 0.02382774 | O24: 0.023458106 | P24: 0.023144445
A25: BOL | B25: Bolivia | C25: PAHO | D25: Lower middle income | E25: 2 | F25: 0.03984027 | G25: 0.039338116 | H25: 0.0388977 | I25: 0.038462851 | J25: 0.038045369 | K25: 0.037639708 | L25: 0.037242576 | M25: 0.036893739 | N25: 0.036533266 | O25: 0.036167391 | P25: 0.035789315
A26: BIH | B26: Bosnia and Herzegovina | C26: EURO | D26: Upper middle income | E26: 1 | F26: 0.018528586 | G26: 0.01860821 | H26: 0.01885568 | I26: 0.019095115 | J26: 0.019330177 | K26: 0.019531033 | L26: 0.019721808 | M26: 0.019843689 | N26: 0.019953957 | O26: 0.020046693 | P26: 0.020129921
A27: BWA | B27: Botswana | C27: AFRO | D27: Upper middle income | E27: 2 | F27: 0.041048005 | G27: 0.040762533 | H27: 0.040231023 | I27: 0.039808829 | J27: 0.03939744 | K27: 0.039010542 | L27: 0.038703223 | M27: 0.038366884 | N27: 0.038056994 | O27: 0.037734204 | P27: 0.037388043
A28: BRA | B28: Brazil | C28: PAHO | D28: Upper middle income | E28: Key | F28: 0.025772601 | G28: 0.025594821 | H28: 0.025361329 | I28: 0.025145397 | J28: 0.024925449 | K28: 0.024704173 | L28: 0.024534883 | M28: 0.024275793 | N28: 0.024064316 | O28: 0.023871448 | P28: 0.023708963
A29: BRN | B29: Brunei Darussalam | C29: WPRO | D29: High income | E29: 1 | F29: 0.025429162 | G29: 0.025050794 | H29: 0.024790542 | I29: 0.024611457 | J29: 0.024481905 | K29: 0.024369883 | L29: 0.024279387 | M29: 0.024241878 | N29: 0.024212522 | O29: 0.024204078 | P29: 0.02421945
A30: BGR | B30: Bulgaria | C30: EURO | D30: Upper middle income | E30: 1 | F30: 0.021665205 | G30: 0.021729011 | H30: 0.02179339 | I30: 0.021868429 | J30: 0.021966965 | K30: 0.022102355 | L30: 0.022308168 | M30: 0.02253504 | N30: 0.022790657 | O30: 0.023053033 | P30: 0.023308968
A31: BFA | B31: Burkina Faso | C31: AFRO | D31: Low income | E31: 3 | F31: 0.064324172 | G31: 0.063804698 | H31: 0.063107426 | I31: 0.062483972 | J31: 0.061854264 | K31: 0.061221065 | L31: 0.06062622 | M31: 0.059956511 | N31: 0.05931906 | O31: 0.058675207 | P31: 0.058024967
A32: BDI | B32: Burundi | C32: AFRO | D32: Low income | E32: 3 | F32: 0.064039107 | G32: 0.063330324 | H32: 0.062666926 | I32: 0.062054006 | J32: 0.061465949 | K32: 0.060886423 | L32: 0.06035091 | M32: 0.059748884 | N32: 0.059190383 | O32: 0.058638038 | P32: 0.058093178
A33: KHM | B33: Cambodia | C33: WPRO | D33: Lower middle income | E33: 4 | F33: 0.03767014 | G33: 0.037414479 | H33: 0.037148336 | I33: 0.036929656 | J33: 0.036716222 | K33: 0.036496793 | L33: 0.036366882 | M33: 0.036064594 | N33: 0.03583159 | O33: 0.035557677 | P33: 0.035212203
A34: CMR | B34: Cameroon | C34: AFRO | D34: Lower middle income | E34: 3 | F34: 0.059233829 | G34: 0.058722876 | H34: 0.05805879 | I34: 0.057477655 | J34: 0.056910701 | K34: 0.056363365 | L34: 0.055871812 | M34: 0.055354491 | N34: 0.054869106 | O34: 0.054384587 | P34: 0.053894685
A35: CAN | B35: Canada | C35: PAHO | D35: High income | E35: 1 | F35: 0.025053229 | G35: 0.025004145 | H35: 0.024987838 | I35: 0.02490821 | J35: 0.024828127 | K35: 0.024770504 | L35: 0.024688589 | M35: 0.024777261 | N35: 0.024806333 | O35: 0.024843124 | P35: 0.024881196
A36: CPV | B36: Cape Verde | C36: AFRO | D36: Lower middle income | E36: 2 | F36: 0.031964447 | G36: 0.031547288 | H36: 0.031126188 | I36: 0.030802466 | J36: 0.030499096 | K36: 0.030197299 | L36: 0.029989569 | M36: 0.029594089 | N36: 0.029298707 | O36: 0.029017392 | P36: 0.028753167
A37: CAF | B37: Central African Republic | C37: AFRO | D37: Low income | E37: 3 | F37: 0.061398332 | G37: 0.060651176 | H37: 0.059764973 | I37: 0.058925037 | J37: 0.058056023 | K37: 0.057153135 | L37: 0.056223146 | M37: 0.055270778 | N37: 0.054317784 | O37: 0.05337976 | P37: 0.052469039
A38: TCD | B38: Chad | C38: AFRO | D38: Low income | E38: Key | F38: 0.06842242 | G38: 0.067659527 | H38: 0.066774186 | I38: 0.065974979 | J38: 0.065180267 | K38: 0.064384699 | L38: 0.063634793 | M38: 0.062730495 | N38: 0.061924234 | O38: 0.061144338 | P38: 0.06039636
A39: CHL | B39: Chile | C39: PAHO | D39: High income | E39: 2 | F39: 0.024803196 | G39: 0.024504319 | H39: 0.024578196 | I39: 0.024634037 | J39: 0.024691259 | K39: 0.024683126 | L39: 0.024656422 | M39: 0.024469253 | N39: 0.024301135 | O39: 0.024151549 | P39: 0.024056527
A40: CHN | B40: China | C40: WPRO | D40: Upper middle income | E40: 1 | F40: 0.022810438 | G40: 0.022935075 | H40: 0.022912124 | I40: 0.02298869 | J40: 0.023084225 | K40: 0.023195375 | L40: 0.023379525 | M40: 0.023464637 | N40: 0.023604148 | O40: 0.023745236 | P40: 0.023879894
A41: COL | B41: Colombia | C41: PAHO | D41: Upper middle income | E41: 2 | F41: 0.02736059 | G41: 0.027167275 | H41: 0.02686667 | I41: 0.026584221 | J41: 0.026300869 | K41: 0.026030567 | L41: 0.025819273 | M41: 0.025539646 | N41: 0.025306893 | O41: 0.025090454 | P41: 0.024897217
...

Sheet 2e. 2-15 pop
A1: Title | B1: 2-15 year old population
A2: Datasource | B2: UN WPP, Revision 2020
A4: ISO | B4: Country | C4: WHO | D4: WB Group (June 2020) | E4: MR MAP Group | F4: 2030 | G4: 2031 | H4: 2032 | I4: 2033 | J4: 2034 | K4: 2035 | L4: 2036 | M4: 2037 | N4: 2038 | O4: 2039 | P4: 2040
A5: AFG | B5: Afghanistan | C5: EMRO | D5: Low income | E5: Key | F5: 15935891 | G5: 16008429 | H5: 16077203 | I5: 16138363 | J5: 16191875 | K5: 16237399 | L5: 16278500 | M5: 16316156 | N5: 16343789 | O5: 16363325 | P5: 16375047
A6: ALB | B6: Albania | C6: EURO | D6: Upper middle income | E6: 1 | F6: 427080 | G6: 418790 | H6: 409949 | I6: 400851 | J6: 391235 | K6: 381137 | L6: 371146 | M6: 361243 | N6: 351218 | O6: 341335 | P6: 331826
A7: DZA | B7: Algeria | C7: AFRO | D7: Lower middle income | E7: 2 | F7: 13046543 | G7: 12887832 | H7: 12711745 | I7: 12492628 | J7: 12263228 | K7: 12045726 | L7: 11860513 | M7: 11704063 | N7: 11575251 | O7: 11476725 | P7: 11405031
A8: AND | B8: Andorra | C8: EURO | D8: High income | E8: 1 | F8: 0 | G8: 0 | H8: 0 | I8: 0 | J8: 0 | K8: 0 | L8: 0 | M8: 0 | N8: 0 | O8: 0 | P8: 0
A9: AGO | B9: Angola | C9: AFRO | D9: Lower middle income | E9: 3 | F9: 17462579 | G9: 17890038 | H9: 18330644 | I9: 18777284 | J9: 19231097 | K9: 19689174 | L9: 20166715 | M9: 20648519 | N9: 21128180 | O9: 21607087 | P9: 22084332
A10: ATG | B10: Antigua And Barbuda | C10: PAHO | D10: High income | E10: 1 | F10: 0 | G10: 19867 | H10: 19748 | I10: 19596 | J10: 19439 | K10: 19274 | L10: 19124 | M10: 18980 | N10: 18841 | O10: 18710 | P10: 18581
A11: ARG | B11: Argentina | C11: PAHO | D11: Upper middle income | E11: 1 | F11: 10371772 | G11: 10359037 | H11: 10344432 | I11: 10323518 | J11: 10299477 | K11: 10273134 | L11: 10249941 | M11: 10224526 | N11: 10199325 | O11: 10172327 | P11: 10142628
A12: ARM | B12: Armenia | C12: EURO | D12: Upper middle income | E12: 1 | F12: 521394 | G12: 509451 | H12: 497713 | I12: 485950 | J12: 474625 | K12: 464049 | L12: 454654 | M12: 446682 | N12: 439644 | O12: 433827 | P12: 429212
A13: AUS | B13: Australia | C13: WPRO | D13: High income | E13: 1 | F13: 4864993 | G13: 4874862 | H13: 4879073 | I13: 4873961 | J13: 4864335 | K13: 4853478 | L13: 4854809 | M13: 4856588 | N13: 4859279 | O13: 4863106 | P13: 4867707
A14: AUT | B14: Austria | C14: EURO | D14: High income | E14: 1 | F14: 1266064 | G14: 1267452 | H14: 1266001 | I14: 1262319 | J14: 1256590 | K14: 1249367 | L14: 1242427 | M14: 1234039 | N14: 1224910 | O14: 1215136 | P14: 1204934
A15: AZE | B15: Azerbaijan | C15: EURO | D15: Upper middle income | E15: 1 | F15: 2079065 | G15: 2032360 | H15: 1989105 | I15: 1945631 | J15: 1905770 | K15: 1870855 | L15: 1845566 | M15: 1827451 | N15: 1812990 | O15: 1803588 | P15: 1797725
A16: BHS | B16: Bahamas | C16: PAHO | D16: High income | E16: 1 | F16: 76523 | G16: 76842 | H16: 77037 | I16: 77085 | J16: 77024 | K16: 76901 | L16: 76858 | M16: 76712 | N16: 76530 | O16: 76276 | P16: 75961
A17: BHR | B17: Bahrain | C17: EMRO | D17: High income | E17: 1 | F17: 309281 | G17: 310619 | H17: 310769 | I17: 310967 | J17: 311421 | K17: 312025 | L17: 313305 | M17: 313433 | N17: 312663 | O17: 311904 | P17: 311336
A18: BGD | B18: Bangladesh | C18: SEARO | D18: Lower middle income | E18: Key | F18: 38688644 | G18: 38333914 | H18: 37959476 | I18: 37576295 | J18: 37175707 | K18: 36759102 | L18: 36330736 | M18: 35902942 | N18: 35460160 | O18: 35014366 | P18: 34571254
A19: BRB | B19: Barbados | C19: PAHO | D19: High income | E19: 1 | F19: 42073 | G19: 42043 | H19: 42010 | I19: 41952 | J19: 41876 | K19: 41776 | L19: 41699 | M19: 41597 | N19: 41456 | O19: 41281 | P19: 41066
A20: BLR | B20: Belarus | C20: EURO | D20: Upper middle income | E20: 2 | F20: 1461982 | G20: 1431907 | H20: 1401673 | I20: 1376366 | J20: 1352589 | K20: 1328756 | L20: 1307310 | M20: 1287034 | N20: 1267160 | O20: 1249222 | P20: 1234421
A21: BEL | B21: Belgium | C21: EURO | D21: High income | E21: 1 | F21: 1795261 | G21: 1787120 | H21: 1778966 | I21: 1772661 | J21: 1766893 | K21: 1761014 | L21: 1757198 | M21: 1753328 | N21: 1749446 | O21: 1745836 | P21: 1742814
A22: BLZ | B22: Belize | C22: PAHO | D22: Upper middle income | E22: 1 | F22: 112537 | G22: 112842 | H22: 112982 | I22: 113094 | J22: 113089 | K22: 112939 | L22: 112827 | M22: 112565 | N22: 112170 | O22: 111664 | P22: 111077
A23: BEN | B23: Benin | C23: AFRO | D23: Lower middle income | E23: 3 | F23: 5566595 | G23: 5672422 | H23: 5778723 | I23: 5882719 | J23: 5985405 | K23: 6086677 | L23: 6194791 | M23: 6302083 | N23: 6406154 | O23: 6507813 | P23: 6607098
A24: BTN | B24: Bhutan | C24: SEARO | D24: Lower middle income | E24: 2 | F24: 170956 | G24: 169566 | H24: 167852 | I24: 165731 | J24: 163320 | K24: 160776 | L24: 158234 | M24: 155652 | N24: 153008 | O24: 150348 | P24: 147704
A25: BOL | B25: Bolivia | C25: PAHO | D25: Lower middle income | E25: 2 | F25: 3309194 | G25: 3314863 | H25: 3320244 | I25: 3325905 | J25: 3330686 | K25: 3333654 | L25: 3336952 | M25: 3338056 | N25: 3337238 | O25: 3334205 | P25: 3329193
A26: BIH | B26: Bosnia and Herzegovina | C26: EURO | D26: Upper middle income | E26: 1 | F26: 352146 | G26: 344718 | H26: 338331 | I26: 333419 | J26: 329471 | K26: 326028 | L26: 323268 | M26: 320877 | N26: 318666 | O26: 316661 | P26: 314861
A27: BWA | B27: Botswana | C27: AFRO | D27: Upper middle income | E27: 2 | F27: 748781 | G27: 748402 | H27: 748262 | I27: 747662 | J27: 747209 | K27: 747098 | L27: 748145 | M27: 749561 | N27: 751274 | O27: 753228 | P27: 755213
A28: BRA | B28: Brazil | C28: PAHO | D28: Upper middle income | E28: Key | F28: 38735617 | G28: 38359705 | H28: 37957109 | I28: 37511101 | J28: 37041695 | K28: 36567060 | L28: 36139315 | M28: 35726683 | N28: 35310193 | O28: 34901568 | P28: 34499649
A29: BRN | B29: Brunei Darussalam | C29: WPRO | D29: High income | E29: 1 | F29: 84730 | G29: 83417 | H29: 82197 | I29: 81111 | J29: 80109 | K29: 79125 | L29: 78226 | M29: 77331 | N29: 76468 | O29: 75619 | P29: 74809
A30: BGR | B30: Bulgaria | C30: EURO | D30: Upper middle income | E30: 1 | F30: 831673 | G30: 820594 | H30: 809998 | I30: 799891 | J30: 790349 | K30: 781450 | L30: 772847 | M30: 765104 | N30: 758096 | O30: 751810 | P30: 746234
A31: BFA | B31: Burkina Faso | C31: AFRO | D31: Low income | E31: 3 | F31: 10176200 | G31: 10373148 | H31: 10573258 | I31: 10769826 | J31: 10965280 | K31: 11159492 | L31: 11362283 | M31: 11564782 | N31: 11763196 | O31: 11957875 | P31: 12148058
A32: BDI | B32: Burundi | C32: AFRO | D32: Low income | E32: 3 | F32: 5967828 | G32: 6068099 | H32: 6167346 | I32: 6265775 | J32: 6363677 | K32: 6461254 | L32: 6564792 | M32: 6669297 | N32: 6773114 | O32: 6877298 | P32: 6982181
A33: KHM | B33: Cambodia | C33: WPRO | D33: Lower middle income | E33: 4 | F33: 4811071 | G33: 4786877 | H33: 4762211 | I33: 4736139 | J33: 4710367 | K33: 4686320 | L33: 4667041 | M33: 4652813 | N33: 4639761 | O33: 4629445 | P33: 4621192
A34: CMR | B34: Cameroon | C34: AFRO | D34: Lower middle income | E34: 3 | F34: 11872714 | G34: 12051085 | H34: 12231395 | I34: 12406676 | J34: 12579989 | K34: 12751232 | L34: 12933828 | M34: 13114940 | N34: 13292091 | O34: 13465568 | P34: 13635016
A35: CAN | B35: Canada | C35: PAHO | D35: High income | E35: 1 | F35: 5717569 | G35: 5744380 | H35: 5759264 | I35: 5767562 | J35: 5770235 | K35: 5769089 | L35: 5792078 | M35: 5804705 | N35: 5816028 | O35: 5823944 | P35: 5828769
A36: CPV | B36: Cape Verde | C36: AFRO | D36: Lower middle income | E36: 2 | F36: 138181 | G36: 136605 | H36: 135119 | I36: 133645 | J36: 132209 | K36: 130802 | L36: 129409 | M36: 128158 | N36: 126894 | O36: 125697 | P36: 124586
A37: CAF | B37: Central African Republic | C37: AFRO | D37: Low income | E37: 3 | F37: 2125259 | G37: 2157070 | H37: 2190272 | I37: 2223706 | J37: 2256696 | K37: 2287899 | L37: 2319200 | M37: 2347786 | N37: 2373219 | O37: 2395313 | P37: 2414144
A38: TCD | B38: Chad | C38: AFRO | D38: Low income | E38: Key | F38: 8435298 | G38: 8600128 | H38: 8762546 | I38: 8917932 | J38: 9067972 | K38: 9212879 | L38: 9368260 | M38: 9520424 | N38: 9663551 | O38: 9800344 | P38: 9931538
A39: CHL | B39: Chile | C39: PAHO | D39: High income | E39: 2 | F39: 3123788 | G39: 3088189 | H39: 3054659 | I39: 3028386 | J39: 3003849 | K39: 2977860 | L39: 2957669 | M39: 2936566 | N39: 2912650 | O39: 2888397 | P39: 2864950
A40: CHN | B40: China | C40: WPRO | D40: Upper middle income | E40: 1 | F40: 219846657 | G40: 2.1673429e+08 | H40: 2.1368838e+08 | I40: 2.1047623e+08 | J40: 2.0734165e+08 | K40: 204399168 | L40: 201956963 | M40: 199818145 | N40: 197872652 | O40: 196169930 | P40: 1.9465207e+08
A41: COL | B41: Colombia | C41: PAHO | D41: Upper middle income | E41: 2 | F41: 9825721 | G41: 9735344 | H41: 9636684 | I41: 9523106 | J41: 9402334 | K41: 9281242 | L41: 9171377 | M41: 9066258 | N41: 8962128 | O41: 8861023 | P41: 8762047
...

Sheet 2f. 2-15 pop %
A1: Title | B1: 2-15 year olds % to total population (up to 65 years of age)
A2: Datasource | B2: UN WPP, Revision 2020
A4: ISO | B4: Country | C4: WHO | D4: WB Group (June 2020) | E4: MR MAP Group | F4: 2030 | G4: 2031 | H4: 2032 | I4: 2033 | J4: 2034 | K4: 2035 | L4: 2036 | M4: 2037 | N4: 2038 | O4: 2039 | P4: 2040
A5: AFG | B5: Afghanistan | C5: EMRO | D5: Low income | E5: Key | F5: 0.2906081 | G5: 0.2895676 | H5: 0.28827639 | I5: 0.28676242 | J5: 0.28503541 | K5: 0.28312336 | L5: 0.28120304 | M5: 0.27906447 | N5: 0.27681779 | O5: 0.27458948 | P5: 0.27246342
A6: ALB | B6: Albania | C6: EURO | D6: Upper middle income | E6: 1 | F6: 0.20279867 | G6: 0.20094913 | H6: 0.19943209 | I6: 0.19841682 | J6: 0.19813039 | K6: 0.19869632 | L6: 0.19973309 | M6: 0.20147072 | N6: 0.20360344 | O6: 0.205536 | P6: 0.2067936
A7: DZA | B7: Algeria | C7: AFRO | D7: Lower middle income | E7: 2 | F7: 0.22305993 | G7: 0.22997539 | H7: 0.2375006 | I7: 0.24525523 | J7: 0.25245124 | K7: 0.25839963 | L7: 0.26292257 | M7: 0.265944 | N7: 0.26748403 | O7: 0.26778472 | P7: 0.26711184
A8: AND | B8: Andorra | C8: EURO | D8: High income | E8: 1 | F8: 0 | G8: 0 | H8: 0 | I8: 0 | J8: 0 | K8: 0 | L8: 0 | M8: 0 | N8: 0 | O8: 0 | P8: 0
A9: AGO | B9: Angola | C9: AFRO | D9: Lower middle income | E9: 3 | F9: 0.26660704 | G9: 0.26769134 | H9: 0.2684869 | I9: 0.2689615 | J9: 0.26913623 | K9: 0.26908133 | L9: 0.26884794 | M9: 0.26846311 | N9: 0.267964 | O9: 0.26739892 | P9: 0.26680483
A10: ATG | B10: Antigua And Barbuda | C10: PAHO | D10: High income | E10: 1 | F10: 0 | G10: 0.21321275 | H10: 0.21388722 | I10: 0.21492436 | J10: 0.21615439 | K10: 0.21741276 | L10: 0.21879152 | M10: 0.22015151 | N10: 0.22130705 | O10: 0.22211929 | P10: 0.22256839
A11: ARG | B11: Argentina | C11: PAHO | D11: Upper middle income | E11: 1 | F11: 0.23267597 | G11: 0.23238547 | H11: 0.23204675 | I11: 0.23166917 | J11: 0.23127127 | K11: 0.23086642 | L11: 0.23057356 | M11: 0.23023897 | N11: 0.22983072 | O11: 0.22934068 | P11: 0.22878819
A12: ARM | B12: Armenia | C12: EURO | D12: Upper middle income | E12: 1 | F12: 0.20703112 | G12: 0.21159494 | H12: 0.21592682 | I12: 0.21981009 | J12: 0.22299042 | K12: 0.2253084 | L12: 0.22675837 | M12: 0.22714711 | N12: 0.2265353 | O12: 0.22511212 | P12: 0.22306414
A13: AUS | B13: Australia | C13: WPRO | D13: High income | E13: 1 | F13: 0.21321692 | G13: 0.21510928 | H13: 0.21717826 | I13: 0.21927136 | J13: 0.2211491 | K13: 0.2226246 | L13: 0.22378957 | M13: 0.22453306 | N13: 0.2249042 | O13: 0.22499291 | P13: 0.22483926
A14: AUT | B14: Austria | C14: EURO | D14: High income | E14: 1 | F14: 0.17874308 | G14: 0.17936843 | H14: 0.18037418 | I14: 0.18173454 | J14: 0.18333952 | K14: 0.18502168 | L14: 0.18704807 | M14: 0.18906354 | N14: 0.19098112 | O14: 0.19271982 | P14: 0.1942291
A15: AZE | B15: Azerbaijan | C15: EURO | D15: Upper middle income | E15: 1 | F15: 0.20957963 | G15: 0.21448689 | H15: 0.21938335 | I15: 0.22405378 | J15: 0.22819787 | K15: 0.231587 | L15: 0.23425699 | M15: 0.23610545 | N15: 0.23685578 | O15: 0.23628886 | P15: 0.23440459
A16: BHS | B16: Bahamas | C16: PAHO | D16: High income | E16: 1 | F16: 0.23208566 | G16: 0.22861815 | H16: 0.2254772 | I16: 0.22260328 | J16: 0.21986603 | K16: 0.21714356 | L16: 0.21467975 | M16: 0.21224208 | N16: 0.21005698 | O16: 0.20838607 | P16: 0.20736212
A17: BHR | B17: Bahrain | C17: EMRO | D17: High income | E17: 1 | F17: 0.2362443 | G17: 0.23297647 | H17: 0.22936798 | I17: 0.22525741 | J17: 0.22092801 | K17: 0.21651844 | L17: 0.21479912 | M17: 0.21457155 | N17: 0.21492251 | O17: 0.21471775 | P17: 0.21314773
A18: BGD | B18: Bangladesh | C18: SEARO | D18: Lower middle income | E18: Key | F18: 0.24555174 | G18: 0.24320315 | H18: 0.24081639 | I18: 0.23848365 | J18: 0.23629195 | K18: 0.23427648 | L18: 0.2325854 | M18: 0.23102074 | N18: 0.22955621 | O18: 0.22812567 | P18: 0.22668743
A19: BRB | B19: Barbados | C19: PAHO | D19: High income | E19: 1 | F19: 0.21112056 | G19: 0.20891064 | H19: 0.20647514 | I19: 0.20397161 | J19: 0.20157243 | K19: 0.19944059 | L19: 0.19768893 | M19: 0.19619576 | N19: 0.19509191 | O19: 0.19438474 | P19: 0.19409183
A20: BLR | B20: Belarus | C20: EURO | D20: Upper middle income | E20: 2 | F20: 0.18877514 | G20: 0.19519125 | H20: 0.20038147 | I20: 0.20434764 | J20: 0.20760712 | K20: 0.21070738 | L20: 0.21388861 | M20: 0.21694005 | N20: 0.2195914 | O20: 0.22132638 | P20: 0.22173227
A21: BEL | B21: Belgium | C21: EURO | D21: High income | E21: 1 | F21: 0.20575113 | G21: 0.20740643 | H21: 0.20885572 | I21: 0.20999155 | J21: 0.21075331 | K21: 0.21114661 | L21: 0.21147823 | M21: 0.21147363 | N21: 0.21117329 | O21: 0.21065042 | P21: 0.20994984
A22: BLZ | B22: Belize | C22: PAHO | D22: Upper middle income | E22: 1 | F22: 0.25529512 | G22: 0.25228961 | H22: 0.24931554 | I22: 0.24649172 | J22: 0.24399079 | K22: 0.24193885 | L22: 0.24037184 | M22: 0.23928628 | N22: 0.238576 | O22: 0.23800856 | P22: 0.23737233
A23: BEN | B23: Benin | C23: AFRO | D23: Lower middle income | E23: 3 | F23: 0.26499289 | G23: 0.26507601 | H23: 0.26513691 | I23: 0.26515805 | J23: 0.26511972 | K23: 0.26501811 | L23: 0.26477484 | M23: 0.26449191 | N23: 0.2641829 | O23: 0.26386175 | P23: 0.26353794
A24: BTN | B24: Bhutan | C24: SEARO | D24: Lower middle income | E24: 2 | F24: 0.23515732 | G24: 0.23170663 | H24: 0.22885631 | I24: 0.22657152 | J24: 0.22463864 | K24: 0.22281267 | L24: 0.22139504 | M24: 0.21997291 | N24: 0.21856351 | O24: 0.21723286 | P24: 0.21602611
A25: BOL | B25: Bolivia | C25: PAHO | D25: Lower middle income | E25: 2 | F25: 0.25930561 | G25: 0.25748742 | H25: 0.2555031 | I25: 0.25340626 | J25: 0.25132397 | K25: 0.24937496 | L25: 0.24766599 | M25: 0.24609879 | N25: 0.24467542 | O25: 0.24336265 | P25: 0.24212581
A26: BIH | B26: Bosnia and Herzegovina | C26: EURO | D26: Upper middle income | E26: 1 | F26: 0.19647382 | G26: 0.19628648 | H26: 0.19683073 | I26: 0.19746723 | J26: 0.19731209 | K26: 0.19595309 | L26: 0.19381614 | M26: 0.19070221 | N26: 0.18694365 | O26: 0.18311654 | P26: 0.17958383
A27: BWA | B27: Botswana | C27: AFRO | D27: Upper middle income | E27: 2 | F27: 0.26200819 | G27: 0.26259399 | H27: 0.26284952 | I27: 0.2627672 | J27: 0.26235528 | K27: 0.26162396 | L27: 0.26074645 | M27: 0.25959459 | N27: 0.2581233 | O27: 0.25633869 | P27: 0.2543006
A28: BRA | B28: Brazil | C28: PAHO | D28: Upper middle income | E28: Key | F28: 0.21713061 | G28: 0.21522532 | H28: 0.21358799 | I28: 0.21226483 | J28: 0.2112205 | K28: 0.21037367 | L28: 0.20974286 | M28: 0.20925986 | N28: 0.20883611 | O28: 0.20836765 | P28: 0.20781156
A29: BRN | B29: Brunei Darussalam | C29: WPRO | D29: High income | E29: 1 | F29: 0.21623563 | G29: 0.2161105 | H29: 0.21573699 | I29: 0.21517425 | J29: 0.21463411 | K29: 0.21433423 | L29: 0.21450142 | M29: 0.21500017 | N29: 0.21550525 | O29: 0.21556024 | P29: 0.21486174
A30: BGR | B30: Bulgaria | C30: EURO | D30: Upper middle income | E30: 1 | F30: 0.18721429 | G30: 0.19013062 | H30: 0.19269279 | I30: 0.19473035 | J30: 0.19609173 | K30: 0.19671814 | L30: 0.19676603 | M30: 0.19592907 | N30: 0.19454024 | O30: 0.19313541 | P30: 0.19207185
A31: BFA | B31: Burkina Faso | C31: AFRO | D31: Low income | E31: 3 | F31: 0.27067645 | G31: 0.27100843 | H31: 0.27123606 | I31: 0.27134864 | J31: 0.27132087 | K31: 0.27114789 | L31: 0.27073242 | M31: 0.27018096 | N31: 0.26955296 | O31: 0.26893384 | P31: 0.26838674
A32: BDI | B32: Burundi | C32: AFRO | D32: Low income | E32: 3 | F32: 0.26428133 | G32: 0.26671844 | H32: 0.26896322 | I32: 0.27093355 | J32: 0.27254599 | K32: 0.27375479 | L32: 0.2745214 | M32: 0.27491643 | N32: 0.27494938 | O32: 0.27464938 | P32: 0.27405338
A33: KHM | B33: Cambodia | C33: WPRO | D33: Lower middle income | E33: 4 | F33: 0.24530499 | G33: 0.2464309 | H33: 0.24790294 | I33: 0.24946522 | J33: 0.25073427 | K33: 0.25146641 | L33: 0.25168 | M33: 0.25130434 | N33: 0.2504663 | O33: 0.2492194 | P33: 0.24752944
A34: CMR | B34: Cameroon | C34: AFRO | D34: Lower middle income | E34: 3 | F34: 0.27059837 | G34: 0.2711068 | H34: 0.27142572 | I34: 0.27154793 | J34: 0.27147742 | K34: 0.27123254 | L34: 0.27077334 | M34: 0.27015631 | N34: 0.2694172 | O34: 0.26860803 | P34: 0.26777
